<?xml version="1.0" ?>
<robot name="ARM" xmlns:xacro="http://www.ros.org/wiki/xacro">

<xacro:include filename="$(find ARM_description)/urdf/materials.xacro" />
<xacro:include filename="$(find ARM_description)/urdf/ARM.trans" />
<xacro:include filename="$(find ARM_description)/urdf/ARM.gazebo" />
<link name="base_link">
  <inertial>
    <origin xyz="-0.0943192644700731 0.6324939187407336 1.2300335636796926" rpy="0 0 0"/>
    <mass value="17.972639999999924"/>
    <inertia ixx="1.833137" iyy="1.542102" izz="1.955592" ixy="0.030245" iyz="-0.287683" ixz="0.030749"/>
  </inertial>
  <visual>
    <origin xyz="0 0 0" rpy="0 0 0"/>
    <geometry>
      <mesh filename="package://ARM_description/meshes/base_link.stl" scale="0.001 0.001 0.001"/>
    </geometry>
    <material name="silver"/>
  </visual>
  <collision>
    <origin xyz="0 0 0" rpy="0 0 0"/>
    <geometry>
      <mesh filename="package://ARM_description/meshes/base_link.stl" scale="0.001 0.001 0.001"/>
    </geometry>
  </collision>
</link>

<link name="foundation__base_1">
  <inertial>
    <origin xyz="-0.0018870401351480243 0.0011126603112967537 0.22948417314037695" rpy="0 0 0"/>
    <mass value="920.5891115290578"/>
    <inertia ixx="49.008853" iyy="41.326946" izz="48.583423" ixy="0.000676" iyz="0.059387" ixz="-0.042227"/>
  </inertial>
  <visual>
    <origin xyz="0.069502 -0.180301 -0.998971" rpy="0 0 0"/>
    <geometry>
      <mesh filename="package://ARM_description/meshes/foundation__base_1.stl" scale="0.001 0.001 0.001"/>
    </geometry>
    <material name="silver"/>
  </visual>
  <collision>
    <origin xyz="0.069502 -0.180301 -0.998971" rpy="0 0 0"/>
    <geometry>
      <mesh filename="package://ARM_description/meshes/foundation__base_1.stl" scale="0.001 0.001 0.001"/>
    </geometry>
  </collision>
</link>

<link name="foundation_fork_1">
  <inertial>
    <origin xyz="0.01203063625955944 -0.7762383950072915 -0.20101382259554024" rpy="0 0 0"/>
    <mass value="2.104746277879827"/>
    <inertia ixx="0.018556" iyy="0.020959" izz="0.025011" ixy="-0.000116" iyz="0.001413" ixz="-6.6e-05"/>
  </inertial>
  <visual>
    <origin xyz="0.08002 -1.072948 -1.882011" rpy="0 0 0"/>
    <geometry>
      <mesh filename="package://ARM_description/meshes/foundation_fork_1.stl" scale="0.001 0.001 0.001"/>
    </geometry>
    <material name="silver"/>
  </visual>
  <collision>
    <origin xyz="0.08002 -1.072948 -1.882011" rpy="0 0 0"/>
    <geometry>
      <mesh filename="package://ARM_description/meshes/foundation_fork_1.stl" scale="0.001 0.001 0.001"/>
    </geometry>
  </collision>
</link>

<link name="forearm_1">
  <inertial>
    <origin xyz="-0.09916108196856231 0.044701985304532454 -0.0004329499526189995" rpy="0 0 0"/>
    <mass value="1.1768759803243096"/>
    <inertia ixx="0.036476" iyy="0.011213" izz="0.046655" ixy="0.001166" iyz="-3.2e-05" ixz="1e-06"/>
  </inertial>
  <visual>
    <origin xyz="-0.020403 -0.334441 -1.858971" rpy="0 0 0"/>
    <geometry>
      <mesh filename="package://ARM_description/meshes/forearm_1.stl" scale="0.001 0.001 0.001"/>
    </geometry>
    <material name="silver"/>
  </visual>
  <collision>
    <origin xyz="-0.020403 -0.334441 -1.858971" rpy="0 0 0"/>
    <geometry>
      <mesh filename="package://ARM_description/meshes/forearm_1.stl" scale="0.001 0.001 0.001"/>
    </geometry>
  </collision>
</link>

<link name="hand_fork_1">
  <inertial>
    <origin xyz="0.15286733204406416 -0.8018817859326866 -1.8339702634743285" rpy="0 0 0"/>
    <mass value="0.1951503912229445"/>
    <inertia ixx="0.000118" iyy="0.000407" izz="0.000457" ixy="-1.3e-05" iyz="0.0" ixz="1e-06"/>
  </inertial>
  <visual>
    <origin xyz="0.270261 -1.980123 -3.692941" rpy="0 0 0"/>
    <geometry>
      <mesh filename="package://ARM_description/meshes/hand_fork_1.stl" scale="0.001 0.001 0.001"/>
    </geometry>
    <material name="silver"/>
  </visual>
  <collision>
    <origin xyz="0.270261 -1.980123 -3.692941" rpy="0 0 0"/>
    <geometry>
      <mesh filename="package://ARM_description/meshes/hand_fork_1.stl" scale="0.001 0.001 0.001"/>
    </geometry>
  </collision>
</link>

<link name="hand_1">
  <inertial>
    <origin xyz="1.6334270761926517 1.4353654409365944 -0.04610029978628982" rpy="0 0 0"/>
    <mass value="0.39305569098005755"/>
    <inertia ixx="0.008981" iyy="0.00079" izz="0.00939" ixy="0.000378" iyz="0.000236" ixz="-1.1e-05"/>
  </inertial>
  <visual>
    <origin xyz="1.734856 0.603817 -1.910738" rpy="0 0 0"/>
    <geometry>
      <mesh filename="package://ARM_description/meshes/hand_1.stl" scale="0.001 0.001 0.001"/>
    </geometry>
    <material name="silver"/>
  </visual>
  <collision>
    <origin xyz="1.734856 0.603817 -1.910738" rpy="0 0 0"/>
    <geometry>
      <mesh filename="package://ARM_description/meshes/hand_1.stl" scale="0.001 0.001 0.001"/>
    </geometry>
  </collision>
</link>

<link name="end_effector_1">
  <inertial>
    <origin xyz="-0.035464288776805644 0.1832519688023635 4.18455210566826e-05" rpy="0 0 0"/>
    <mass value="0.5354810781353946"/>
    <inertia ixx="0.003594" iyy="0.000283" izz="0.003616" ixy="0.00013" iyz="0.0" ixz="0.0"/>
  </inertial>
  <visual>
    <origin xyz="0.0936 -1.205018 -1.858932" rpy="0 0 0"/>
    <geometry>
      <mesh filename="package://ARM_description/meshes/end_effector_1.stl" scale="0.001 0.001 0.001"/>
    </geometry>
    <material name="silver"/>
  </visual>
  <collision>
    <origin xyz="0.0936 -1.205018 -1.858932" rpy="0 0 0"/>
    <geometry>
      <mesh filename="package://ARM_description/meshes/end_effector_1.stl" scale="0.001 0.001 0.001"/>
    </geometry>
  </collision>
</link>

<joint name="rigid_1" type="fixed">
  <origin xyz="-0.069502 0.180301 0.998971" rpy="0 0 0"/>
  <parent link="base_link"/>
  <child link="foundation__base_1"/>
</joint>

<joint name="revolute_1" type="continuous">
  <origin xyz="-0.010518 0.892647 0.88304" rpy="0 0 0"/>
  <parent link="foundation__base_1"/>
  <child link="foundation_fork_1"/>
  <axis xyz="-0.0 -0.0 1.0"/>
</joint>

<joint name="revolute_2" type="continuous">
  <origin xyz="0.100423 -0.738507 -0.02304" rpy="0 0 0"/>
  <parent link="foundation_fork_1"/>
  <child link="forearm_1"/>
  <axis xyz="-0.998941 -0.046 0.0"/>
</joint>

<joint name="revolute_3" type="continuous">
  <origin xyz="1.464595 2.58394 1.782203" rpy="0 0 0"/>
  <parent link="hand_1"/>
  <child link="hand_fork_1"/>
  <axis xyz="0.046 -0.998941 -0.0"/>
</joint>

<joint name="revolute_4" type="continuous">
  <origin xyz="-1.755259 -0.938258 0.051767" rpy="0 0 0"/>
  <parent link="forearm_1"/>
  <child link="hand_1"/>
  <axis xyz="-0.998941 -0.046 0.0"/>
</joint>

<joint name="revolute_5" type="continuous">
  <origin xyz="0.176661 -0.775105 -1.834009" rpy="0 0 0"/>
  <parent link="hand_fork_1"/>
  <child link="end_effector_1"/>
  <axis xyz="-0.99894 -0.046 0.001551"/>
</joint>

</robot>
